{
 "cells": [
  {
   "cell_type": "markdown",
   "metadata": {},
   "source": [
    "# connect tws inside notebook"
   ]
  },
  {
   "cell_type": "code",
   "execution_count": null,
   "metadata": {},
   "outputs": [
    {
     "name": "stderr",
     "output_type": "stream",
     "text": [
      "API connection failed: ConnectionRefusedError(111, \"Connect call failed ('127.0.0.1', 4796)\")\n",
      "Make sure API port on TWS/IBG is open\n"
     ]
    },
    {
     "ename": "ConnectionRefusedError",
     "evalue": "[Errno 111] Connect call failed ('127.0.0.1', 4796)",
     "output_type": "error",
     "traceback": [
      "\u001b[0;31m---------------------------------------------------------------------------\u001b[0m",
      "\u001b[0;31mConnectionRefusedError\u001b[0m                    Traceback (most recent call last)",
      "Cell \u001b[0;32mIn[3], line 4\u001b[0m\n\u001b[1;32m      2\u001b[0m util\u001b[38;5;241m.\u001b[39mstartLoop()\n\u001b[1;32m      3\u001b[0m ib \u001b[38;5;241m=\u001b[39m IB()\n\u001b[0;32m----> 4\u001b[0m \u001b[43mib\u001b[49m\u001b[38;5;241;43m.\u001b[39;49m\u001b[43mconnect\u001b[49m\u001b[43m(\u001b[49m\u001b[43mport\u001b[49m\u001b[38;5;241;43m=\u001b[39;49m\u001b[38;5;241;43m4796\u001b[39;49m\u001b[43m,\u001b[49m\u001b[43m \u001b[49m\u001b[43mclientId\u001b[49m\u001b[38;5;241;43m=\u001b[39;49m\u001b[38;5;241;43m33\u001b[39;49m\u001b[43m)\u001b[49m\n",
      "File \u001b[0;32m~/python_try_out_ib_async/.venv/lib/python3.11/site-packages/ib_async/ib.py:367\u001b[0m, in \u001b[0;36mIB.connect\u001b[0;34m(self, host, port, clientId, timeout, readonly, account, raiseSyncErrors, fetchFields)\u001b[0m\n\u001b[1;32m    327\u001b[0m \u001b[38;5;28;01mdef\u001b[39;00m\u001b[38;5;250m \u001b[39m\u001b[38;5;21mconnect\u001b[39m(\n\u001b[1;32m    328\u001b[0m     \u001b[38;5;28mself\u001b[39m,\n\u001b[1;32m    329\u001b[0m     host: \u001b[38;5;28mstr\u001b[39m \u001b[38;5;241m=\u001b[39m \u001b[38;5;124m\"\u001b[39m\u001b[38;5;124m127.0.0.1\u001b[39m\u001b[38;5;124m\"\u001b[39m,\n\u001b[0;32m   (...)\u001b[0m\n\u001b[1;32m    336\u001b[0m     fetchFields: StartupFetch \u001b[38;5;241m=\u001b[39m StartupFetchALL,\n\u001b[1;32m    337\u001b[0m ):\n\u001b[1;32m    338\u001b[0m \u001b[38;5;250m    \u001b[39m\u001b[38;5;124;03m\"\"\"\u001b[39;00m\n\u001b[1;32m    339\u001b[0m \u001b[38;5;124;03m    Connect to a running TWS or IB gateway application.\u001b[39;00m\n\u001b[1;32m    340\u001b[0m \u001b[38;5;124;03m    After the connection is made the client is fully synchronized\u001b[39;00m\n\u001b[0;32m   (...)\u001b[0m\n\u001b[1;32m    365\u001b[0m \u001b[38;5;124;03m          to the ``fetchFields`` parameter as needed.\u001b[39;00m\n\u001b[1;32m    366\u001b[0m \u001b[38;5;124;03m    \"\"\"\u001b[39;00m\n\u001b[0;32m--> 367\u001b[0m     \u001b[38;5;28;01mreturn\u001b[39;00m \u001b[38;5;28;43mself\u001b[39;49m\u001b[38;5;241;43m.\u001b[39;49m\u001b[43m_run\u001b[49m\u001b[43m(\u001b[49m\n\u001b[1;32m    368\u001b[0m \u001b[43m        \u001b[49m\u001b[38;5;28;43mself\u001b[39;49m\u001b[38;5;241;43m.\u001b[39;49m\u001b[43mconnectAsync\u001b[49m\u001b[43m(\u001b[49m\n\u001b[1;32m    369\u001b[0m \u001b[43m            \u001b[49m\u001b[43mhost\u001b[49m\u001b[43m,\u001b[49m\n\u001b[1;32m    370\u001b[0m \u001b[43m            \u001b[49m\u001b[43mport\u001b[49m\u001b[43m,\u001b[49m\n\u001b[1;32m    371\u001b[0m \u001b[43m            \u001b[49m\u001b[43mclientId\u001b[49m\u001b[43m,\u001b[49m\n\u001b[1;32m    372\u001b[0m \u001b[43m            \u001b[49m\u001b[43mtimeout\u001b[49m\u001b[43m,\u001b[49m\n\u001b[1;32m    373\u001b[0m \u001b[43m            \u001b[49m\u001b[43mreadonly\u001b[49m\u001b[43m,\u001b[49m\n\u001b[1;32m    374\u001b[0m \u001b[43m            \u001b[49m\u001b[43maccount\u001b[49m\u001b[43m,\u001b[49m\n\u001b[1;32m    375\u001b[0m \u001b[43m            \u001b[49m\u001b[43mraiseSyncErrors\u001b[49m\u001b[43m,\u001b[49m\n\u001b[1;32m    376\u001b[0m \u001b[43m            \u001b[49m\u001b[43mfetchFields\u001b[49m\u001b[43m,\u001b[49m\n\u001b[1;32m    377\u001b[0m \u001b[43m        \u001b[49m\u001b[43m)\u001b[49m\n\u001b[1;32m    378\u001b[0m \u001b[43m    \u001b[49m\u001b[43m)\u001b[49m\n",
      "File \u001b[0;32m~/python_try_out_ib_async/.venv/lib/python3.11/site-packages/ib_async/ib.py:418\u001b[0m, in \u001b[0;36mIB._run\u001b[0;34m(self, *awaitables)\u001b[0m\n\u001b[1;32m    417\u001b[0m \u001b[38;5;28;01mdef\u001b[39;00m\u001b[38;5;250m \u001b[39m\u001b[38;5;21m_run\u001b[39m(\u001b[38;5;28mself\u001b[39m, \u001b[38;5;241m*\u001b[39mawaitables: Awaitable):\n\u001b[0;32m--> 418\u001b[0m     \u001b[38;5;28;01mreturn\u001b[39;00m \u001b[43mutil\u001b[49m\u001b[38;5;241;43m.\u001b[39;49m\u001b[43mrun\u001b[49m\u001b[43m(\u001b[49m\u001b[38;5;241;43m*\u001b[39;49m\u001b[43mawaitables\u001b[49m\u001b[43m,\u001b[49m\u001b[43m \u001b[49m\u001b[43mtimeout\u001b[49m\u001b[38;5;241;43m=\u001b[39;49m\u001b[38;5;28;43mself\u001b[39;49m\u001b[38;5;241;43m.\u001b[39;49m\u001b[43mRequestTimeout\u001b[49m\u001b[43m)\u001b[49m\n",
      "File \u001b[0;32m~/python_try_out_ib_async/.venv/lib/python3.11/site-packages/ib_async/util.py:360\u001b[0m, in \u001b[0;36mrun\u001b[0;34m(timeout, *awaitables)\u001b[0m\n\u001b[1;32m    358\u001b[0m globalErrorEvent\u001b[38;5;241m.\u001b[39mconnect(onError)\n\u001b[1;32m    359\u001b[0m \u001b[38;5;28;01mtry\u001b[39;00m:\n\u001b[0;32m--> 360\u001b[0m     result \u001b[38;5;241m=\u001b[39m \u001b[43mloop\u001b[49m\u001b[38;5;241;43m.\u001b[39;49m\u001b[43mrun_until_complete\u001b[49m\u001b[43m(\u001b[49m\u001b[43mtask\u001b[49m\u001b[43m)\u001b[49m\n\u001b[1;32m    361\u001b[0m \u001b[38;5;28;01mexcept\u001b[39;00m asyncio\u001b[38;5;241m.\u001b[39mCancelledError \u001b[38;5;28;01mas\u001b[39;00m e:\n\u001b[1;32m    362\u001b[0m     \u001b[38;5;28;01mraise\u001b[39;00m globalErrorEvent\u001b[38;5;241m.\u001b[39mvalue() \u001b[38;5;129;01mor\u001b[39;00m e\n",
      "File \u001b[0;32m~/python_try_out_ib_async/.venv/lib/python3.11/site-packages/nest_asyncio.py:98\u001b[0m, in \u001b[0;36m_patch_loop.<locals>.run_until_complete\u001b[0;34m(self, future)\u001b[0m\n\u001b[1;32m     95\u001b[0m \u001b[38;5;28;01mif\u001b[39;00m \u001b[38;5;129;01mnot\u001b[39;00m f\u001b[38;5;241m.\u001b[39mdone():\n\u001b[1;32m     96\u001b[0m     \u001b[38;5;28;01mraise\u001b[39;00m \u001b[38;5;167;01mRuntimeError\u001b[39;00m(\n\u001b[1;32m     97\u001b[0m         \u001b[38;5;124m'\u001b[39m\u001b[38;5;124mEvent loop stopped before Future completed.\u001b[39m\u001b[38;5;124m'\u001b[39m)\n\u001b[0;32m---> 98\u001b[0m \u001b[38;5;28;01mreturn\u001b[39;00m \u001b[43mf\u001b[49m\u001b[38;5;241;43m.\u001b[39;49m\u001b[43mresult\u001b[49m\u001b[43m(\u001b[49m\u001b[43m)\u001b[49m\n",
      "File \u001b[0;32m/usr/lib/python3.11/asyncio/futures.py:203\u001b[0m, in \u001b[0;36mFuture.result\u001b[0;34m(self)\u001b[0m\n\u001b[1;32m    201\u001b[0m \u001b[38;5;28mself\u001b[39m\u001b[38;5;241m.\u001b[39m__log_traceback \u001b[38;5;241m=\u001b[39m \u001b[38;5;28;01mFalse\u001b[39;00m\n\u001b[1;32m    202\u001b[0m \u001b[38;5;28;01mif\u001b[39;00m \u001b[38;5;28mself\u001b[39m\u001b[38;5;241m.\u001b[39m_exception \u001b[38;5;129;01mis\u001b[39;00m \u001b[38;5;129;01mnot\u001b[39;00m \u001b[38;5;28;01mNone\u001b[39;00m:\n\u001b[0;32m--> 203\u001b[0m     \u001b[38;5;28;01mraise\u001b[39;00m \u001b[38;5;28mself\u001b[39m\u001b[38;5;241m.\u001b[39m_exception\u001b[38;5;241m.\u001b[39mwith_traceback(\u001b[38;5;28mself\u001b[39m\u001b[38;5;241m.\u001b[39m_exception_tb)\n\u001b[1;32m    204\u001b[0m \u001b[38;5;28;01mreturn\u001b[39;00m \u001b[38;5;28mself\u001b[39m\u001b[38;5;241m.\u001b[39m_result\n",
      "File \u001b[0;32m/usr/lib/python3.11/asyncio/tasks.py:267\u001b[0m, in \u001b[0;36mTask.__step\u001b[0;34m(***failed resolving arguments***)\u001b[0m\n\u001b[1;32m    263\u001b[0m \u001b[38;5;28;01mtry\u001b[39;00m:\n\u001b[1;32m    264\u001b[0m     \u001b[38;5;28;01mif\u001b[39;00m exc \u001b[38;5;129;01mis\u001b[39;00m \u001b[38;5;28;01mNone\u001b[39;00m:\n\u001b[1;32m    265\u001b[0m         \u001b[38;5;66;03m# We use the `send` method directly, because coroutines\u001b[39;00m\n\u001b[1;32m    266\u001b[0m         \u001b[38;5;66;03m# don't have `__iter__` and `__next__` methods.\u001b[39;00m\n\u001b[0;32m--> 267\u001b[0m         result \u001b[38;5;241m=\u001b[39m \u001b[43mcoro\u001b[49m\u001b[38;5;241;43m.\u001b[39;49m\u001b[43msend\u001b[49m\u001b[43m(\u001b[49m\u001b[38;5;28;43;01mNone\u001b[39;49;00m\u001b[43m)\u001b[49m\n\u001b[1;32m    268\u001b[0m     \u001b[38;5;28;01melse\u001b[39;00m:\n\u001b[1;32m    269\u001b[0m         result \u001b[38;5;241m=\u001b[39m coro\u001b[38;5;241m.\u001b[39mthrow(exc)\n",
      "File \u001b[0;32m~/python_try_out_ib_async/.venv/lib/python3.11/site-packages/ib_async/ib.py:2020\u001b[0m, in \u001b[0;36mIB.connectAsync\u001b[0;34m(self, host, port, clientId, timeout, readonly, account, raiseSyncErrors, fetchFields)\u001b[0m\n\u001b[1;32m   2017\u001b[0m timeout \u001b[38;5;241m=\u001b[39m timeout \u001b[38;5;129;01mor\u001b[39;00m \u001b[38;5;28;01mNone\u001b[39;00m\n\u001b[1;32m   2018\u001b[0m \u001b[38;5;28;01mtry\u001b[39;00m:\n\u001b[1;32m   2019\u001b[0m     \u001b[38;5;66;03m# establish API connection\u001b[39;00m\n\u001b[0;32m-> 2020\u001b[0m     \u001b[38;5;28;01mawait\u001b[39;00m \u001b[38;5;28mself\u001b[39m\u001b[38;5;241m.\u001b[39mclient\u001b[38;5;241m.\u001b[39mconnectAsync(host, port, clientId, timeout)\n\u001b[1;32m   2022\u001b[0m     \u001b[38;5;66;03m# autobind manual orders\u001b[39;00m\n\u001b[1;32m   2023\u001b[0m     \u001b[38;5;28;01mif\u001b[39;00m clientId \u001b[38;5;241m==\u001b[39m \u001b[38;5;241m0\u001b[39m:\n",
      "File \u001b[0;32m~/python_try_out_ib_async/.venv/lib/python3.11/site-packages/ib_async/client.py:217\u001b[0m, in \u001b[0;36mClient.connectAsync\u001b[0;34m(self, host, port, clientId, timeout)\u001b[0m\n\u001b[1;32m    215\u001b[0m \u001b[38;5;28mself\u001b[39m\u001b[38;5;241m.\u001b[39mconnState \u001b[38;5;241m=\u001b[39m Client\u001b[38;5;241m.\u001b[39mCONNECTING\n\u001b[1;32m    216\u001b[0m timeout \u001b[38;5;241m=\u001b[39m timeout \u001b[38;5;129;01mor\u001b[39;00m \u001b[38;5;28;01mNone\u001b[39;00m\n\u001b[0;32m--> 217\u001b[0m \u001b[38;5;28;01mawait\u001b[39;00m asyncio\u001b[38;5;241m.\u001b[39mwait_for(\u001b[38;5;28mself\u001b[39m\u001b[38;5;241m.\u001b[39mconn\u001b[38;5;241m.\u001b[39mconnectAsync(host, port), timeout)\n\u001b[1;32m    218\u001b[0m \u001b[38;5;28mself\u001b[39m\u001b[38;5;241m.\u001b[39m_logger\u001b[38;5;241m.\u001b[39minfo(\u001b[38;5;124m\"\u001b[39m\u001b[38;5;124mConnected\u001b[39m\u001b[38;5;124m\"\u001b[39m)\n\u001b[1;32m    219\u001b[0m msg \u001b[38;5;241m=\u001b[39m \u001b[38;5;124mb\u001b[39m\u001b[38;5;124m\"\u001b[39m\u001b[38;5;124mAPI\u001b[39m\u001b[38;5;130;01m\\0\u001b[39;00m\u001b[38;5;124m\"\u001b[39m \u001b[38;5;241m+\u001b[39m \u001b[38;5;28mself\u001b[39m\u001b[38;5;241m.\u001b[39m_prefix(\n\u001b[1;32m    220\u001b[0m     \u001b[38;5;124mb\u001b[39m\u001b[38;5;124m\"\u001b[39m\u001b[38;5;124mv\u001b[39m\u001b[38;5;132;01m%d\u001b[39;00m\u001b[38;5;124m..\u001b[39m\u001b[38;5;132;01m%d\u001b[39;00m\u001b[38;5;132;01m%s\u001b[39;00m\u001b[38;5;124m\"\u001b[39m\n\u001b[1;32m    221\u001b[0m     \u001b[38;5;241m%\u001b[39m (\n\u001b[0;32m   (...)\u001b[0m\n\u001b[1;32m    225\u001b[0m     )\n\u001b[1;32m    226\u001b[0m )\n",
      "File \u001b[0;32m/usr/lib/python3.11/asyncio/tasks.py:479\u001b[0m, in \u001b[0;36mwait_for\u001b[0;34m(fut, timeout)\u001b[0m\n\u001b[1;32m    476\u001b[0m         \u001b[38;5;28;01mraise\u001b[39;00m\n\u001b[1;32m    478\u001b[0m \u001b[38;5;28;01mif\u001b[39;00m fut\u001b[38;5;241m.\u001b[39mdone():\n\u001b[0;32m--> 479\u001b[0m     \u001b[38;5;28;01mreturn\u001b[39;00m \u001b[43mfut\u001b[49m\u001b[38;5;241;43m.\u001b[39;49m\u001b[43mresult\u001b[49m\u001b[43m(\u001b[49m\u001b[43m)\u001b[49m\n\u001b[1;32m    480\u001b[0m \u001b[38;5;28;01melse\u001b[39;00m:\n\u001b[1;32m    481\u001b[0m     fut\u001b[38;5;241m.\u001b[39mremove_done_callback(cb)\n",
      "File \u001b[0;32m/usr/lib/python3.11/asyncio/futures.py:203\u001b[0m, in \u001b[0;36mFuture.result\u001b[0;34m(self)\u001b[0m\n\u001b[1;32m    201\u001b[0m \u001b[38;5;28mself\u001b[39m\u001b[38;5;241m.\u001b[39m__log_traceback \u001b[38;5;241m=\u001b[39m \u001b[38;5;28;01mFalse\u001b[39;00m\n\u001b[1;32m    202\u001b[0m \u001b[38;5;28;01mif\u001b[39;00m \u001b[38;5;28mself\u001b[39m\u001b[38;5;241m.\u001b[39m_exception \u001b[38;5;129;01mis\u001b[39;00m \u001b[38;5;129;01mnot\u001b[39;00m \u001b[38;5;28;01mNone\u001b[39;00m:\n\u001b[0;32m--> 203\u001b[0m     \u001b[38;5;28;01mraise\u001b[39;00m \u001b[38;5;28mself\u001b[39m\u001b[38;5;241m.\u001b[39m_exception\u001b[38;5;241m.\u001b[39mwith_traceback(\u001b[38;5;28mself\u001b[39m\u001b[38;5;241m.\u001b[39m_exception_tb)\n\u001b[1;32m    204\u001b[0m \u001b[38;5;28;01mreturn\u001b[39;00m \u001b[38;5;28mself\u001b[39m\u001b[38;5;241m.\u001b[39m_result\n",
      "File \u001b[0;32m/usr/lib/python3.11/asyncio/tasks.py:269\u001b[0m, in \u001b[0;36mTask.__step\u001b[0;34m(***failed resolving arguments***)\u001b[0m\n\u001b[1;32m    267\u001b[0m         result \u001b[38;5;241m=\u001b[39m coro\u001b[38;5;241m.\u001b[39msend(\u001b[38;5;28;01mNone\u001b[39;00m)\n\u001b[1;32m    268\u001b[0m     \u001b[38;5;28;01melse\u001b[39;00m:\n\u001b[0;32m--> 269\u001b[0m         result \u001b[38;5;241m=\u001b[39m \u001b[43mcoro\u001b[49m\u001b[38;5;241;43m.\u001b[39;49m\u001b[43mthrow\u001b[49m\u001b[43m(\u001b[49m\u001b[43mexc\u001b[49m\u001b[43m)\u001b[49m\n\u001b[1;32m    270\u001b[0m \u001b[38;5;28;01mexcept\u001b[39;00m \u001b[38;5;167;01mStopIteration\u001b[39;00m \u001b[38;5;28;01mas\u001b[39;00m exc:\n\u001b[1;32m    271\u001b[0m     \u001b[38;5;28;01mif\u001b[39;00m \u001b[38;5;28mself\u001b[39m\u001b[38;5;241m.\u001b[39m_must_cancel:\n\u001b[1;32m    272\u001b[0m         \u001b[38;5;66;03m# Task is cancelled right before coro stops.\u001b[39;00m\n",
      "File \u001b[0;32m~/python_try_out_ib_async/.venv/lib/python3.11/site-packages/ib_async/connection.py:39\u001b[0m, in \u001b[0;36mConnection.connectAsync\u001b[0;34m(self, host, port)\u001b[0m\n\u001b[1;32m     37\u001b[0m \u001b[38;5;28mself\u001b[39m\u001b[38;5;241m.\u001b[39mreset()\n\u001b[1;32m     38\u001b[0m loop \u001b[38;5;241m=\u001b[39m getLoop()\n\u001b[0;32m---> 39\u001b[0m \u001b[38;5;28mself\u001b[39m\u001b[38;5;241m.\u001b[39mtransport, _ \u001b[38;5;241m=\u001b[39m \u001b[38;5;28;01mawait\u001b[39;00m loop\u001b[38;5;241m.\u001b[39mcreate_connection(\u001b[38;5;28;01mlambda\u001b[39;00m: \u001b[38;5;28mself\u001b[39m, host, port)\n",
      "File \u001b[0;32m/usr/lib/python3.11/asyncio/base_events.py:1085\u001b[0m, in \u001b[0;36mBaseEventLoop.create_connection\u001b[0;34m(self, protocol_factory, host, port, ssl, family, proto, flags, sock, local_addr, server_hostname, ssl_handshake_timeout, ssl_shutdown_timeout, happy_eyeballs_delay, interleave)\u001b[0m\n\u001b[1;32m   1083\u001b[0m \u001b[38;5;28;01mtry\u001b[39;00m:\n\u001b[1;32m   1084\u001b[0m     \u001b[38;5;28;01mif\u001b[39;00m \u001b[38;5;28mlen\u001b[39m(exceptions) \u001b[38;5;241m==\u001b[39m \u001b[38;5;241m1\u001b[39m:\n\u001b[0;32m-> 1085\u001b[0m         \u001b[38;5;28;01mraise\u001b[39;00m exceptions[\u001b[38;5;241m0\u001b[39m]\n\u001b[1;32m   1086\u001b[0m     \u001b[38;5;28;01melse\u001b[39;00m:\n\u001b[1;32m   1087\u001b[0m         \u001b[38;5;66;03m# If they all have the same str(), raise one.\u001b[39;00m\n\u001b[1;32m   1088\u001b[0m         model \u001b[38;5;241m=\u001b[39m \u001b[38;5;28mstr\u001b[39m(exceptions[\u001b[38;5;241m0\u001b[39m])\n",
      "File \u001b[0;32m/usr/lib/python3.11/asyncio/base_events.py:1069\u001b[0m, in \u001b[0;36mBaseEventLoop.create_connection\u001b[0;34m(self, protocol_factory, host, port, ssl, family, proto, flags, sock, local_addr, server_hostname, ssl_handshake_timeout, ssl_shutdown_timeout, happy_eyeballs_delay, interleave)\u001b[0m\n\u001b[1;32m   1067\u001b[0m \u001b[38;5;28;01mfor\u001b[39;00m addrinfo \u001b[38;5;129;01min\u001b[39;00m infos:\n\u001b[1;32m   1068\u001b[0m     \u001b[38;5;28;01mtry\u001b[39;00m:\n\u001b[0;32m-> 1069\u001b[0m         sock \u001b[38;5;241m=\u001b[39m \u001b[38;5;28;01mawait\u001b[39;00m \u001b[38;5;28mself\u001b[39m\u001b[38;5;241m.\u001b[39m_connect_sock(\n\u001b[1;32m   1070\u001b[0m             exceptions, addrinfo, laddr_infos)\n\u001b[1;32m   1071\u001b[0m         \u001b[38;5;28;01mbreak\u001b[39;00m\n\u001b[1;32m   1072\u001b[0m     \u001b[38;5;28;01mexcept\u001b[39;00m \u001b[38;5;167;01mOSError\u001b[39;00m:\n",
      "File \u001b[0;32m/usr/lib/python3.11/asyncio/base_events.py:973\u001b[0m, in \u001b[0;36mBaseEventLoop._connect_sock\u001b[0;34m(self, exceptions, addr_info, local_addr_infos)\u001b[0m\n\u001b[1;32m    971\u001b[0m             \u001b[38;5;28;01melse\u001b[39;00m:\n\u001b[1;32m    972\u001b[0m                 \u001b[38;5;28;01mraise\u001b[39;00m \u001b[38;5;167;01mOSError\u001b[39;00m(\u001b[38;5;124mf\u001b[39m\u001b[38;5;124m\"\u001b[39m\u001b[38;5;124mno matching local address with \u001b[39m\u001b[38;5;132;01m{\u001b[39;00mfamily\u001b[38;5;132;01m=}\u001b[39;00m\u001b[38;5;124m found\u001b[39m\u001b[38;5;124m\"\u001b[39m)\n\u001b[0;32m--> 973\u001b[0m     \u001b[38;5;28;01mawait\u001b[39;00m \u001b[38;5;28mself\u001b[39m\u001b[38;5;241m.\u001b[39msock_connect(sock, address)\n\u001b[1;32m    974\u001b[0m     \u001b[38;5;28;01mreturn\u001b[39;00m sock\n\u001b[1;32m    975\u001b[0m \u001b[38;5;28;01mexcept\u001b[39;00m \u001b[38;5;167;01mOSError\u001b[39;00m \u001b[38;5;28;01mas\u001b[39;00m exc:\n",
      "File \u001b[0;32m/usr/lib/python3.11/asyncio/selector_events.py:634\u001b[0m, in \u001b[0;36mBaseSelectorEventLoop.sock_connect\u001b[0;34m(self, sock, address)\u001b[0m\n\u001b[1;32m    632\u001b[0m \u001b[38;5;28mself\u001b[39m\u001b[38;5;241m.\u001b[39m_sock_connect(fut, sock, address)\n\u001b[1;32m    633\u001b[0m \u001b[38;5;28;01mtry\u001b[39;00m:\n\u001b[0;32m--> 634\u001b[0m     \u001b[38;5;28;01mreturn\u001b[39;00m \u001b[38;5;28;01mawait\u001b[39;00m fut\n\u001b[1;32m    635\u001b[0m \u001b[38;5;28;01mfinally\u001b[39;00m:\n\u001b[1;32m    636\u001b[0m     \u001b[38;5;66;03m# Needed to break cycles when an exception occurs.\u001b[39;00m\n\u001b[1;32m    637\u001b[0m     fut \u001b[38;5;241m=\u001b[39m \u001b[38;5;28;01mNone\u001b[39;00m\n",
      "File \u001b[0;32m/usr/lib/python3.11/asyncio/futures.py:287\u001b[0m, in \u001b[0;36mFuture.__await__\u001b[0;34m(self)\u001b[0m\n\u001b[1;32m    285\u001b[0m \u001b[38;5;28;01mif\u001b[39;00m \u001b[38;5;129;01mnot\u001b[39;00m \u001b[38;5;28mself\u001b[39m\u001b[38;5;241m.\u001b[39mdone():\n\u001b[1;32m    286\u001b[0m     \u001b[38;5;28mself\u001b[39m\u001b[38;5;241m.\u001b[39m_asyncio_future_blocking \u001b[38;5;241m=\u001b[39m \u001b[38;5;28;01mTrue\u001b[39;00m\n\u001b[0;32m--> 287\u001b[0m     \u001b[38;5;28;01myield\u001b[39;00m \u001b[38;5;28mself\u001b[39m  \u001b[38;5;66;03m# This tells Task to wait for completion.\u001b[39;00m\n\u001b[1;32m    288\u001b[0m \u001b[38;5;28;01mif\u001b[39;00m \u001b[38;5;129;01mnot\u001b[39;00m \u001b[38;5;28mself\u001b[39m\u001b[38;5;241m.\u001b[39mdone():\n\u001b[1;32m    289\u001b[0m     \u001b[38;5;28;01mraise\u001b[39;00m \u001b[38;5;167;01mRuntimeError\u001b[39;00m(\u001b[38;5;124m\"\u001b[39m\u001b[38;5;124mawait wasn\u001b[39m\u001b[38;5;124m'\u001b[39m\u001b[38;5;124mt used with future\u001b[39m\u001b[38;5;124m\"\u001b[39m)\n",
      "File \u001b[0;32m/usr/lib/python3.11/asyncio/tasks.py:339\u001b[0m, in \u001b[0;36mTask.__wakeup\u001b[0;34m(self, future)\u001b[0m\n\u001b[1;32m    337\u001b[0m \u001b[38;5;28;01mdef\u001b[39;00m\u001b[38;5;250m \u001b[39m\u001b[38;5;21m__wakeup\u001b[39m(\u001b[38;5;28mself\u001b[39m, future):\n\u001b[1;32m    338\u001b[0m     \u001b[38;5;28;01mtry\u001b[39;00m:\n\u001b[0;32m--> 339\u001b[0m         \u001b[43mfuture\u001b[49m\u001b[38;5;241;43m.\u001b[39;49m\u001b[43mresult\u001b[49m\u001b[43m(\u001b[49m\u001b[43m)\u001b[49m\n\u001b[1;32m    340\u001b[0m     \u001b[38;5;28;01mexcept\u001b[39;00m \u001b[38;5;167;01mBaseException\u001b[39;00m \u001b[38;5;28;01mas\u001b[39;00m exc:\n\u001b[1;32m    341\u001b[0m         \u001b[38;5;66;03m# This may also be a cancellation.\u001b[39;00m\n\u001b[1;32m    342\u001b[0m         \u001b[38;5;28mself\u001b[39m\u001b[38;5;241m.\u001b[39m__step(exc)\n",
      "File \u001b[0;32m/usr/lib/python3.11/asyncio/futures.py:203\u001b[0m, in \u001b[0;36mFuture.result\u001b[0;34m(self)\u001b[0m\n\u001b[1;32m    201\u001b[0m \u001b[38;5;28mself\u001b[39m\u001b[38;5;241m.\u001b[39m__log_traceback \u001b[38;5;241m=\u001b[39m \u001b[38;5;28;01mFalse\u001b[39;00m\n\u001b[1;32m    202\u001b[0m \u001b[38;5;28;01mif\u001b[39;00m \u001b[38;5;28mself\u001b[39m\u001b[38;5;241m.\u001b[39m_exception \u001b[38;5;129;01mis\u001b[39;00m \u001b[38;5;129;01mnot\u001b[39;00m \u001b[38;5;28;01mNone\u001b[39;00m:\n\u001b[0;32m--> 203\u001b[0m     \u001b[38;5;28;01mraise\u001b[39;00m \u001b[38;5;28mself\u001b[39m\u001b[38;5;241m.\u001b[39m_exception\u001b[38;5;241m.\u001b[39mwith_traceback(\u001b[38;5;28mself\u001b[39m\u001b[38;5;241m.\u001b[39m_exception_tb)\n\u001b[1;32m    204\u001b[0m \u001b[38;5;28;01mreturn\u001b[39;00m \u001b[38;5;28mself\u001b[39m\u001b[38;5;241m.\u001b[39m_result\n",
      "File \u001b[0;32m/usr/lib/python3.11/asyncio/selector_events.py:674\u001b[0m, in \u001b[0;36mBaseSelectorEventLoop._sock_connect_cb\u001b[0;34m(self, fut, sock, address)\u001b[0m\n\u001b[1;32m    671\u001b[0m     err \u001b[38;5;241m=\u001b[39m sock\u001b[38;5;241m.\u001b[39mgetsockopt(socket\u001b[38;5;241m.\u001b[39mSOL_SOCKET, socket\u001b[38;5;241m.\u001b[39mSO_ERROR)\n\u001b[1;32m    672\u001b[0m     \u001b[38;5;28;01mif\u001b[39;00m err \u001b[38;5;241m!=\u001b[39m \u001b[38;5;241m0\u001b[39m:\n\u001b[1;32m    673\u001b[0m         \u001b[38;5;66;03m# Jump to any except clause below.\u001b[39;00m\n\u001b[0;32m--> 674\u001b[0m         \u001b[38;5;28;01mraise\u001b[39;00m \u001b[38;5;167;01mOSError\u001b[39;00m(err, \u001b[38;5;124mf\u001b[39m\u001b[38;5;124m'\u001b[39m\u001b[38;5;124mConnect call failed \u001b[39m\u001b[38;5;132;01m{\u001b[39;00maddress\u001b[38;5;132;01m}\u001b[39;00m\u001b[38;5;124m'\u001b[39m)\n\u001b[1;32m    675\u001b[0m \u001b[38;5;28;01mexcept\u001b[39;00m (\u001b[38;5;167;01mBlockingIOError\u001b[39;00m, \u001b[38;5;167;01mInterruptedError\u001b[39;00m):\n\u001b[1;32m    676\u001b[0m     \u001b[38;5;66;03m# socket is still registered, the callback will be retried later\u001b[39;00m\n\u001b[1;32m    677\u001b[0m     \u001b[38;5;28;01mpass\u001b[39;00m\n",
      "\u001b[0;31mConnectionRefusedError\u001b[0m: [Errno 111] Connect call failed ('127.0.0.1', 4796)"
     ]
    }
   ],
   "source": [
    "from ib_async import *\n",
    "util.startLoop()\n",
    "ib = IB()\n",
    "ib.connect(port=7496, clientId=33)\n"
   ]
  }
 ],
 "metadata": {
  "kernelspec": {
   "display_name": ".venv",
   "language": "python",
   "name": "python3"
  },
  "language_info": {
   "codemirror_mode": {
    "name": "ipython",
    "version": 3
   },
   "file_extension": ".py",
   "mimetype": "text/x-python",
   "name": "python",
   "nbconvert_exporter": "python",
   "pygments_lexer": "ipython3",
   "version": "3.11.2"
  }
 },
 "nbformat": 4,
 "nbformat_minor": 2
}
